Workbook

Sheet Summary
A1: Lab highlights: the data behind the slides
A2: Yellow cells = measured values typed from each submitted report. Everything else is a formula.
A4: Lab | B4: Result | C4: Value | D4: Compared with | E4: Sheet
A5: ECE 302 Lab 2: ±10 V dual-rail supply | B5: + rail regulation (measured) | C5: =PowerSupply!F6 -> 0.24836082 | D5: limit 5 % | E5: PowerSupply
B6: − rail ripple (measured) | C6: =PowerSupply!F9 -> 7.8431373 | D6: limit 0.5 % | E6: PowerSupply
A7: ECE 203 Lab 6: filters and resonance | B7: RLC centre frequency error | C7: =Filters!L8 -> -0.0039581805 | D7: theory =Filters!K8 | E7: Filters
B8: Capacitance implied by RC cut-off | C8: =Filters!L12 -> 94.986687 | D8: nominal 100 nF | E8: Filters
A9: PHYS 230 Lab 4: Faraday's law | B9: Solenoid fit R² | C9: =Faraday!H6 -> 0.9997691 | D9: 1 = perfectly linear | E9: Faraday
B10: Earth's field B | C10: =Faraday!H11 -> 3.2289951e-05 | D10: gaussmeter 2.45e-5 T | E10: Faraday
A11: ECE 340 Lab 2: sampling and aliasing | B11: Max |10 Hz − 90 Hz| sample difference | C11: =Aliasing!E3 -> 2.3203661e-14 | D11: 0 means indistinguishable | E11: Aliasing

Sheet Filters
A1: ECE 203 Lab 6: four filters, measured against theory
A2: R = 470 Ω, C = 100 nF, L = 10 mH (values from the report). Theory gain is a formula of f.
J4: R (Ω) | K4: 470
J5: C (F) | K5: 1e-07
J6: L (H) | K6: 0.01
J7: Quantity | K7: Theory | L7: Measured / error
J8: RLC f₀ = 1/(2π√LC) | K8: =1/(2*PI()*SQRT(K6*K5)) -> 5032.9212 | L8: =(5013-K8)/K8 -> -0.0039581805
J9: RC f꜀ = 1/(2πRC) | K9: =1/(2*PI()*K4*K5) -> 3386.2754 | L9: =(3565-K9)/K9 -> 0.052779114
J10: RL f꜀ = R/(2πL) | K10: =K4/(2*PI()*K6) -> 7480.2823 | L10: =(7300-K10)/K10 -> -0.024101005
J11: RLC bandwidth = R/(2πL) | K11: =K4/(2*PI()*K6) -> 7480.2823 | L11: =10281-2690 -> 7591
J12: C implied by measured RC f꜀ (nF) | K12: =K5*1000000000 -> 100 | L12: =1/(2*PI()*K4*3565)*1000000000 -> 94.986687
A14: RC low-pass
A15: f (Hz) | B15: Vout/Vin | C15: Theory | D15: Error | F15: Measured dB | G15: Theory dB
A16: 100 | B16: 0.999 | C16: =1/SQRT(1+(A16/$K$9)^2) -> 0.99956425 | D16: =B16-C16 -> -0.00056424587 | F16: =20*LOG10(B16) -> -0.0086902355 | G16: =20*LOG10(C16) -> -0.0037857372
A17: 500 | B17: 0.99 | C17: =1/SQRT(1+(A17/$K$9)^2) -> 0.98927409 | D17: =B17-C17 -> 0.00072590893 | F17: =20*LOG10(B17) -> -0.087296108 | G17: =20*LOG10(C17) -> -0.093667298
A18: 1000 | B18: 0.961 | C18: =1/SQRT(1+(A18/$K$9)^2) -> 0.95905544 | D18: =B18-C18 -> 0.001944555 | F18: =20*LOG10(B18) -> -0.34553225 | G18: =20*LOG10(C18) -> -0.36312569
A19: 2000 | B19: 0.865 | C19: =1/SQRT(1+(A19/$K$9)^2) -> 0.86103575 | D19: =B19-C19 -> 0.0039642519 | F19: =20*LOG10(B19) -> -1.2596779 | G19: =20*LOG10(C19) -> -1.2995763
A20: 3565 | B20: 0.7 | C20: =1/SQRT(1+(A20/$K$9)^2) -> 0.68869872 | D20: =B20-C20 -> 0.011301277 | F20: =20*LOG10(B20) -> -3.0980392 | G20: =20*LOG10(C20) -> -3.2394144
A21: 5000 | B21: 0.572 | C21: =1/SQRT(1+(A21/$K$9)^2) -> 0.56075491 | D21: =B21-C21 -> 0.011245093 | F21: =20*LOG10(B21) -> -4.8520794 | G21: =20*LOG10(C21) -> -5.0245383
A22: 10000 | B22: 0.335 | C22: =1/SQRT(1+(A22/$K$9)^2) -> 0.32073724 | D22: =B22-C22 -> 0.01426276 | F22: =20*LOG10(B22) -> -9.4991039 | G22: =20*LOG10(C22) -> -9.8770122
A23: 20000 | B23: 0.174 | C23: =1/SQRT(1+(A23/$K$9)^2) -> 0.16693786 | D23: =B23-C23 -> 0.00706214 | F23: =20*LOG10(B23) -> -15.189015 | G23: =20*LOG10(C23) -> -15.548903
A24: 100000 | B24: 0.043 | C24: =1/SQRT(1+(A24/$K$9)^2) -> 0.033843356 | D24: =B24-C24 -> 0.0091566444 | F24: =20*LOG10(B24) -> -27.330631 | G24: =20*LOG10(C24) -> -29.410532
A31: RC high-pass
A32: f (Hz) | B32: Vout/Vin | C32: Theory | D32: Error | F32: Measured dB | G32: Theory dB
A33: 100 | B33: 0.028 | C33: =(A33/$K$9)/SQRT(1+(A33/$K$9)^2) -> 0.029518103 | D33: =B33-C33 -> -0.0015181027 | F33: =20*LOG10(B33) -> -31.056839 | G33: =20*LOG10(C33) -> -30.598231
A34: 500 | B34: 0.14 | C34: =(A34/$K$9)/SQRT(1+(A34/$K$9)^2) -> 0.14607112 | D34: =B34-C34 -> -0.0060711222 | F34: =20*LOG10(B34) -> -17.077439 | G34: =20*LOG10(C34) -> -16.708713
A35: 1000 | B35: 0.268 | C35: =(A35/$K$9)/SQRT(1+(A35/$K$9)^2) -> 0.28321838 | D35: =B35-C35 -> -0.015218385 | F35: =20*LOG10(B35) -> -11.437304 | G35: =20*LOG10(C35) -> -10.957571
A36: 2000 | B36: 0.488 | C36: =(A36/$K$9)/SQRT(1+(A36/$K$9)^2) -> 0.50854443 | D36: =B36-C36 -> -0.020544433 | F36: =20*LOG10(B36) -> -6.2316036 | G36: =20*LOG10(C36) -> -5.8734219
A37: 3568 | B37: 0.701 | C37: =(A37/$K$9)/SQRT(1+(A37/$K$9)^2) -> 0.72533683 | D37: =B37-C37 -> -0.024336832 | F37: =20*LOG10(B37) -> -3.0856396 | G37: =20*LOG10(C37) -> -2.7892054
A38: 5000 | B38: 0.808 | C38: =(A38/$K$9)/SQRT(1+(A38/$K$9)^2) -> 0.82798184 | D38: =B38-C38 -> -0.019981844 | F38: =20*LOG10(B38) -> -1.8517728 | G38: =20*LOG10(C38) -> -1.6395837
A39: 10000 | B39: 0.929 | C39: =(A39/$K$9)/SQRT(1+(A39/$K$9)^2) -> 0.94716821 | D39: =B39-C39 -> -0.018168212 | F39: =20*LOG10(B39) -> -0.63968572 | G39: =20*LOG10(C39) -> -0.47145771
A40: 20000 | B40: 0.963 | C40: =(A40/$K$9)/SQRT(1+(A40/$K$9)^2) -> 0.98596742 | D40: =B40-C40 -> -0.022967419 | F40: =20*LOG10(B40) -> -0.32747426 | G40: =20*LOG10(C40) -> -0.12274872
A41: 100000 | B41: 0.984 | C41: =(A41/$K$9)/SQRT(1+(A41/$K$9)^2) -> 0.99942715 | D41: =B41-C41 -> -0.01542715 | F41: =20*LOG10(B41) -> -0.14009803 | G41: =20*LOG10(C41) -> -0.0049771414
A48: RL low-pass
A49: f (Hz) | B49: Vout/Vin | C49: Theory | D49: Error | F49: Measured dB | G49: Theory dB
A50: 100 | B50: 0.98 | C50: =1/SQRT(1+(A50/$K$10)^2) -> 0.99991065 | D50: =B50-C50 -> -0.019910654 | F50: =20*LOG10(B50) -> -0.17547849 | G50: =20*LOG10(C50) -> -0.00077608542
A51: 1000 | B51: 0.972 | C51: =1/SQRT(1+(A51/$K$10)^2) -> 0.9911822 | D51: =B51-C51 -> -0.019182205 | F51: =20*LOG10(B51) -> -0.2466747 | G51: =20*LOG10(C51) -> -0.076930074
A52: 2000 | B52: 0.95 | C52: =1/SQRT(1+(A52/$K$10)^2) -> 0.96606567 | D52: =B52-C52 -> -0.016065669 | F52: =20*LOG10(B52) -> -0.44552789 | G52: =20*LOG10(C52) -> -0.29986702
A53: 5000 | B53: 0.831 | C53: =1/SQRT(1+(A53/$K$10)^2) -> 0.83137538 | D53: =B53-C53 -> -0.00037538214 | F53: =20*LOG10(B53) -> -1.6079795 | G53: =20*LOG10(C53) -> -1.6040568
A54: 7300 | B54: 0.701 | C54: =1/SQRT(1+(A54/$K$10)^2) -> 0.71567847 | D54: =B54-C54 -> -0.014678471 | F54: =20*LOG10(B54) -> -3.0856396 | G54: =20*LOG10(C54) -> -2.9056409
...

Sheet PowerSupply
A1: ECE 302 Lab 2: ±10 V dual-rail supply (group lab with Rohan Singh)
A2: Voltages from the report. %VR = (V_no-load − V_full-load) / V_full-load. Ripple = Vpp / V_DC.
A4: Rail / source | B4: V no-load | C4: V full-load | D4: Vpp ripple | E4: V DC | F4: Result (%) | G4: Limit (%) | H4: Verdict
A5: + rail, LTspice | B5: 10.04684 | C5: 10.031006 | F5: =(B5-C5)/C5*100 -> 0.15784513 | G5: 5 | H5: =IF(F5<=G5,"PASS","FAIL") -> PASS
A6: + rail, measured | B6: 10.091 | C6: 10.066 | F6: =(B6-C6)/C6*100 -> 0.24836082 | G6: 5 | H6: =IF(F6<=G6,"PASS","FAIL") -> PASS
A7: − rail, LTspice | B7: 10.073769 | C7: 9.9945365 | F7: =(B7-C7)/C7*100 -> 0.79276169 | G7: 5 | H7: =IF(F7<=G7,"PASS","FAIL") -> PASS
A8: − rail, measured | B8: 10.376 | C8: 9.819 | F8: =(B8-C8)/C8*100 -> 5.6726754 | G8: 5 | H8: =IF(F8<=G8,"PASS","FAIL") -> FAIL
A9: − rail ripple, measured | D9: 0.76 | E9: 9.69 | F9: =D9/E9*100 -> 7.8431373 | G9: 0.5 | H9: =IF(F9<=G9,"PASS","FAIL") -> FAIL
A11: Why the Zener rail failed (report): the 235 Ω ballast could not keep the 1N4740 in breakdown at full load, so it dropped out of regulation.
A12: Ballast design check: | B12: =(20.2-10)/(0.021+0.025) -> 221.73913 | C12: Ω needed (Eq. 2.1)

Sheet Faraday
A1: PHYS 230 Lab 4: Faraday's law (with Duong Hung Nguyen and James Pacia)
A2: Fit with SLOPE/INTERCEPT/RSQ; B from the flip coil with fractional error propagation.
A4: Trial | B4: I primary (A) | C4: E secondary (V) | G4: Quantity | H4: Value
A5: 1 | B5: 0.025 | C5: 0.0095 | G5: Slope (V/A) | H5: =SLOPE(C5:C15,B5:B15) -> 0.36927888
A6: 2 | B6: 0.03 | C6: 0.0114 | G6: R² | H6: =RSQ(C5:C15,B5:B15) -> 0.9997691
A7: 3 | B7: 0.033 | C7: 0.0128 | G7: Intercept (mV) | H7: =INTERCEPT(C5:C15,B5:B15)*1000 -> 0.85287667
A8: 4 | B8: 0.037 | C8: 0.0143 | G8: Flip coil mean Ψ (V·s) | H8: =AVERAGE(B20:B29) -> 0.0784
A9: 5 | B9: 0.042 | C9: 0.016 | G9: Standard error of Ψ (V·s) | H9: =_xlfn.STDEV.S(B20:B29)/SQRT(10) -> 0.0014
A10: 6 | B10: 0.052 | C10: 0.0197 | G10: δΨ/Ψ | H10: =H9/H8 -> 0.017857143
A11: 7 | B11: 0.062 | C11: 0.0241 | G11: B = Ψ / (2·G·N·A) (T) | H11: =H8/(2*200*100*0.0607) -> 3.2289951e-05
A12: 8 | B12: 0.083 | C12: 0.0317 | G12: δB = B·√((δΨ/Ψ)² + (δG/G)² + (δA/A)²) | H12: =H11*SQRT(H10^2+0.02^2+0.0072^2) -> 8.9642716e-07
A13: 9 | B13: 0.108 | C13: 0.0415 | G13: Gaussmeter reference (T) | H13: 2.45e-05
A14: 10 | B14: 0.216 | C14: 0.0825 | G14: B vs reference | H14: =(H11-H13)/H13 -> 0.31795717
A15: 11 | B15: 0.493 | C15: 0.182
A18: Flip coil: 10 trials (G = 200, N = 100, A = 0.0607 m²)
A19: Trial | B19: Ψ (V·s)
A20: 1 | B20: 0.072
A21: 2 | B21: 0.077
A22: 3 | B22: 0.082
A23: 4 | B23: 0.085
A24: 5 | B24: 0.077
A25: 6 | B25: 0.075
A26: 7 | B26: 0.073
A27: 8 | B27: 0.084
A28: 9 | B28: 0.079
A29: 10 | B29: 0.08

Sheet Aliasing
A1: ECE 340 Lab 2: why 90 Hz looks like 10 Hz at fs = 100 Hz
A2: x₁ = cos(2π·10·n/fs), x₂ = cos(2π·90·n/fs). Column E is the largest gap. | D2: fs (Hz) | E2: 100
D3: max |x₁−x₂| | E3: =MAX(D6:D36) -> 2.3203661e-14
A5: n | B5: x₁[n] (10 Hz) | C5: x₂[n] (90 Hz) | D5: |x₁−x₂|
A6: 0 | B6: =COS(2*PI()*10*A6/$E$2) -> 1 | C6: =COS(2*PI()*90*A6/$E$2) -> 1 | D6: =ABS(B6-C6) -> 0
A7: 1 | B7: =COS(2*PI()*10*A7/$E$2) -> 0.80901699 | C7: =COS(2*PI()*90*A7/$E$2) -> 0.80901699 | D7: =ABS(B7-C7) -> 1.110223e-16
A8: 2 | B8: =COS(2*PI()*10*A8/$E$2) -> 0.30901699 | C8: =COS(2*PI()*90*A8/$E$2) -> 0.30901699 | D8: =ABS(B8-C8) -> 4.4408921e-16
A9: 3 | B9: =COS(2*PI()*10*A9/$E$2) -> -0.30901699 | C9: =COS(2*PI()*90*A9/$E$2) -> -0.30901699 | D9: =ABS(B9-C9) -> 9.4368957e-16
A10: 4 | B10: =COS(2*PI()*10*A10/$E$2) -> -0.80901699 | C10: =COS(2*PI()*90*A10/$E$2) -> -0.80901699 | D10: =ABS(B10-C10) -> 5.5511151e-16
A11: 5 | B11: =COS(2*PI()*10*A11/$E$2) -> -1 | C11: =COS(2*PI()*90*A11/$E$2) -> -1 | D11: =ABS(B11-C11) -> 0
A12: 6 | B12: =COS(2*PI()*10*A12/$E$2) -> -0.80901699 | C12: =COS(2*PI()*90*A12/$E$2) -> -0.80901699 | D12: =ABS(B12-C12) -> 1.110223e-15
A13: 7 | B13: =COS(2*PI()*10*A13/$E$2) -> -0.30901699 | C13: =COS(2*PI()*90*A13/$E$2) -> -0.30901699 | D13: =ABS(B13-C13) -> 1.7763568e-15
A14: 8 | B14: =COS(2*PI()*10*A14/$E$2) -> 0.30901699 | C14: =COS(2*PI()*90*A14/$E$2) -> 0.30901699 | D14: =ABS(B14-C14) -> 1.8873791e-15
A15: 9 | B15: =COS(2*PI()*10*A15/$E$2) -> 0.80901699 | C15: =COS(2*PI()*90*A15/$E$2) -> 0.80901699 | D15: =ABS(B15-C15) -> 8.8817842e-16
A16: 10 | B16: =COS(2*PI()*10*A16/$E$2) -> 1 | C16: =COS(2*PI()*90*A16/$E$2) -> 1 | D16: =ABS(B16-C16) -> 0
A17: 11 | B17: =COS(2*PI()*10*A17/$E$2) -> 0.80901699 | C17: =COS(2*PI()*90*A17/$E$2) -> 0.80901699 | D17: =ABS(B17-C17) -> 5.5511151e-16
... A36: 30 | B36: =COS(2*PI()*10*A36/$E$2) -> 1 | C36: =COS(2*PI()*90*A36/$E$2) -> 1 | D36: =ABS(B36-C36) -> 0
